root        : INFO     Namespace(cuda=True, dataset_dir='../../dataset1/', filename='main_pytorch', iteration_max=55000, mode='train', subdir='models_test', validate=False, workspace='../../experiment_workspace/Conformer-SST/')
root        : INFO     The data contains: 1000 training and 340 validation data.
Traceback (most recent call last):
  File "main_pytorch.py", line 342, in <module>
    train(args)
  File "main_pytorch.py", line 172, in train
    cuda=cuda)
  File "main_pytorch.py", line 48, in evaluate
    cuda=cuda)
  File "main_pytorch.py", line 99, in forward
    batch_output = model(batch_x,batch_ch,batch_3)
  File "/home/tzhou/miniconda3/envs/py37/lib/python3.7/site-packages/torch/nn/modules/module.py", line 889, in _call_impl
    result = self.forward(*input, **kwargs)
  File "/dstore/home/tzhou/Conformer-S/main/models_pytorch.py", line 377, in forward
    x3 = self.cnn_encoder3(x3)
  File "/home/tzhou/miniconda3/envs/py37/lib/python3.7/site-packages/torch/nn/modules/module.py", line 889, in _call_impl
    result = self.forward(*input, **kwargs)
  File "/dstore/home/tzhou/Conformer-S/main/models_pytorch.py", line 456, in forward
    x = self.conv1(x, pool_size=(2, 2), pool_type='max')
  File "/home/tzhou/miniconda3/envs/py37/lib/python3.7/site-packages/torch/nn/modules/module.py", line 889, in _call_impl
    result = self.forward(*input, **kwargs)
  File "/dstore/home/tzhou/Conformer-S/main/models_pytorch.py", line 81, in forward
    x = F.relu_(self.bn2(self.conv2(x)))
  File "/home/tzhou/miniconda3/envs/py37/lib/python3.7/site-packages/torch/nn/modules/module.py", line 889, in _call_impl
    result = self.forward(*input, **kwargs)
  File "/home/tzhou/miniconda3/envs/py37/lib/python3.7/site-packages/torch/nn/modules/conv.py", line 399, in forward
    return self._conv_forward(input, self.weight, self.bias)
  File "/home/tzhou/miniconda3/envs/py37/lib/python3.7/site-packages/torch/nn/modules/conv.py", line 396, in _conv_forward
    self.padding, self.dilation, self.groups)
RuntimeError: CUDA out of memory. Tried to allocate 80.00 MiB (GPU 0; 10.92 GiB total capacity; 3.26 GiB already allocated; 44.44 MiB free; 3.29 GiB reserved in total by PyTorch)
root        : INFO     Namespace(cuda=True, dataset_dir='../../dataset1/', filename='main_pytorch', iteration_max=55000, mode='inference_validation_data', subdir='models_test', validate=False, workspace='../../experiment_workspace/Conformer-SST/')
param number:
72655682
Traceback (most recent call last):
  File "main_pytorch.py", line 345, in <module>
    inference_validation_data(args)
  File "main_pytorch.py", line 256, in inference_validation_data
    checkpoint = torch.load(model_path)
  File "/home/tzhou/miniconda3/envs/py37/lib/python3.7/site-packages/torch/serialization.py", line 579, in load
    with _open_file_like(f, 'rb') as opened_file:
  File "/home/tzhou/miniconda3/envs/py37/lib/python3.7/site-packages/torch/serialization.py", line 230, in _open_file_like
    return _open_file(name_or_buffer, mode)
  File "/home/tzhou/miniconda3/envs/py37/lib/python3.7/site-packages/torch/serialization.py", line 211, in __init__
    super(_open_file, self).__init__(open(name, mode))
FileNotFoundError: [Errno 2] No such file or directory: '../../experiment_workspace/Conformer-SST/models/models_test/md_55000_iters.tar'
